<script>
    // この関数はawait / asyncで書き換えることはできない
    function promiseFactory(count) {
        return new Promise((resolve, reject) => {
            setTimeout(() => {
                count++;
                console.log(`${count}回目のコールです。時刻：[${new Date().toTimeString()}]`);
                if (count === 3) { // 3回目のコールでエラー
                    reject(count);
                } else {
                    resolve(count);
                }
            }, 1000);
        });
    }
    /* このコードをexecute()で書き換える
    promiseFactory( 0 )
    .then( count => { return promiseFactory( count ); })
    .then( count => { return promiseFactory( count ); })
    .then( count => { return promiseFactory( count ); })
    .catch( errorCount => {
    console.error(`エラーに飛びました。現在のカウントは ${errorCount } です。`);
    }).finally(() => {
    console.log( "処理を終了します。" );
    });
    */
    // await / asyncを使った書き換え
    async function execute() { // awaitを内部で使っているためasyncをつける
        try {
            // promiseFactory内のresolveが呼び出されるまで次の処理を実行しない
            //awaitによってresolveの引数の値がcountに代入される
            let count = await promiseFactory(0);
            count = await promiseFactory(count);
            count = await promiseFactory(count);
            count = await promiseFactory(count);
        } catch (errorCount) {
            // Promiseがrejectedのステータスになった場合はcatchブロックに遷移する
            console.error(`エラーに飛びました。現在のカウントは ${errorCount} です。`);
        } finally {
            console.log("処理を終了します。");
        }
    }
    // execute()の実行
    execute();
    // > 1回目のコールです。時刻：[01:13:26 GMT+0900 (日本標準時)]
    // > 2回目のコールです。時刻：[01:13:27 GMT+0900 (日本標準時)]
    // > 3回目のコールです。時刻：[01:13:28 GMT+0900 (日本標準時)]
    // > エラーに飛びました。現在のカウントは3です。
    // > 処理を終了します。
</script>