<script>
    Promise.reject('エラーの理由
    ').catch(error => {
        console.error(error)
    })

    console.log('グローバルコンテキスト終了')
</script>